Workbook

Sheet Comparison
A1: VTT model metrics: comparison for Qwen2-VL family Hugging Face framework vs MLX framework
A3: Size | B3: Hugging Face framework | O3: MLX framework
B4: Model | C4: Parameters | D4: Avg Inference Rate (tokens/s) | E4: Avg Inference Time (s) | F4: Avg Video Processing Time (s) | G4: Avg Total Time (s) | H4: Avg Time per Output Token (s) | I4: Avg Frames Sampled | J4: Avg Input Tokens | K4: Avg Output Tokens | L4: Avg Output Words | M4: Avg Time to First Token (ms) | N4: Avg Prompt Processing Rate (tokens/s) | O4: Model | P4: Parameters | Q4: Avg Inference Rate (tokens/s) | R4: Avg Inference Time (s) | S4: Avg Video Processing Time (s) | T4: Avg Total Time (s) | U4: Avg Time per Output Token (s) | V4: Avg Frames Sampled | W4: Avg Input Tokens | X4: Avg Output Tokens | Y4: Avg Output Words | Z4: Avg Time to First Token (ms) | AA4: Avg Prompt Processing Rate (tokens/s)
A5: Small | B5: Qwen2-VL-2B-Instruct | C5: 2.21B | D5: 30.54 | E5: 2.93 | F5: 0.0311 | G5: 2.97 | H5: =1/D5 | I5: NA | J5: NA | K5: 88.17 | L5: NA | M5: NA | N5: NA | O5: Qwen2-VL-2B-Instruct | P5: 2.21B | Q5: =AVERAGE(MLX_per_prompt!M2:M11) | R5: =AVERAGE(MLX_per_prompt!N2:N11) | S5: NA | T5: NA | U5: =1/Q5 | V5: =AVERAGE(MLX_per_prompt!G2:G11) | W5: =AVERAGE(MLX_per_prompt!H2:H11) | X5: =AVERAGE(MLX_per_prompt!I2:I11) | Y5: =AVERAGE(MLX_per_prompt!J2:J11) | Z5: =AVERAGE(MLX_per_prompt!K2:K11) | AA5: =AVERAGE(MLX_per_prompt!L2:L11)
A6: Large | B6: Qwen2-VL-7B-Instruct | C6: 8.29B | D6: NA | E6: NA | F6: NA | G6: NA | H6: NA | I6: NA | J6: NA | K6: NA | L6: NA | M6: NA | N6: NA | O6: Qwen2-VL-7B-Instruct | P6: 8.29B | Q6: =AVERAGE(MLX_per_prompt!M12:M21) | R6: =AVERAGE(MLX_per_prompt!N12:N21) | S6: NA | T6: NA | U6: =1/Q6 | V6: =AVERAGE(MLX_per_prompt!G12:G21) | W6: =AVERAGE(MLX_per_prompt!H12:H21) | X6: =AVERAGE(MLX_per_prompt!I12:I21) | Y6: =AVERAGE(MLX_per_prompt!J12:J21) | Z6: =AVERAGE(MLX_per_prompt!K12:K21) | AA6: =AVERAGE(MLX_per_prompt!L12:L21)
A8: MLX vs Hugging Face
A9: Size | B9: Inference rate: MLX ÷ HF (x faster) | C9: Inference time: HF ÷ MLX (x shorter) | D9: Models compared (HF vs MLX)
A10: Small | B10: =Q5/D5 | C10: =E5/R5 | D10: =B5&" vs "&O5
A11: Large | B11: NA | C11: NA | D11: =B6&" vs "&O6
A13: Comparison insights
A14: 1. Same model, both frameworks: the Small row compares Qwen2-VL-2B-Instruct with itself. It generates 307.4 tokens/s on MLX vs 30.54 on Hugging Face, 10.1x faster.
A15: 2. Average inference time is 1.60 s on MLX vs 2.93 s on Hugging Face (1.8x shorter). The gap is smaller than the speed gap because MLX's time includes reading ~2,928 video tokens first (1172 ms to the first token) and MLX wrote longer answers (131 vs 88.17 output tokens).
A16: 3. Each video becomes ~2,928 input tokens on average (248 per sampled frame, and 7,680 for the 30-second clip), so MLX spends 1172 ms (2B) and 2010 ms (7B) reading the video before the first word appears.
A17: 4. Large: Qwen2-VL-7B on MLX runs at 109.6 tokens/s and 3.61 s per video. The Hugging Face Large (Qwen2-VL-7B) metrics weren't provided, so that comparison is NA.
A18: 5. On MLX the 2B model is 2.8x faster than 7B, while 7B writes somewhat longer, more detailed descriptions (175 vs 131 output tokens). Neither model hit the 1024-token limit.
A19: 6. Hugging Face reports a separate video processing time (0.0311 s) and total time (2.97 s); MLX doesn't time video loading separately, so those are NA on MLX. MLX extra metrics: time to first token 1172 / 2010 ms and prompt processing rate 3039 / 1612 tokens/s (2B / 7B).
A25: VTT model metrics: comparison for Qwen2.5-VL family Hugging Face framework vs MLX framework
A27: Size | B27: Hugging Face framework | O27: MLX framework
B28: Model | C28: Parameters | D28: Avg Inference Rate (tokens/s) | E28: Avg Inference Time (s) | F28: Avg Video Processing Time (s) | G28: Avg Total Time (s) | H28: Avg Time per Output Token (s) | I28: Avg Frames Sampled | J28: Avg Input Tokens | K28: Avg Output Tokens | L28: Avg Output Words | M28: Avg Time to First Token (ms) | N28: Avg Prompt Processing Rate (tokens/s) | O28: Model | P28: Parameters | Q28: Avg Inference Rate (tokens/s) | R28: Avg Inference Time (s) | S28: Avg Video Processing Time (s) | T28: Avg Total Time (s) | U28: Avg Time per Output Token (s) | V28: Avg Frames Sampled | W28: Avg Input Tokens | X28: Avg Output Tokens | Y28: Avg Output Words | Z28: Avg Time to First Token (ms) | AA28: Avg Prompt Processing Rate (tokens/s)
A29: Small | B29: Qwen2-VL-2B-Instruct | C29: 2.21B | D29: 30.54 | E29: 2.93 | F29: 0.0311 | G29: 2.97 | H29: =1/D29 | I29: NA | J29: NA | K29: 88.17 | L29: NA | M29: NA | N29: NA | O29: Qwen2.5-VL-3B-Instruct | P29: 3.75B | Q29: =AVERAGE(MLX_per_prompt!M22:M31) | R29: =AVERAGE(MLX_per_prompt!N22:N31) | S29: NA | T29: NA | U29: =1/Q29 | V29: =AVERAGE(MLX_per_prompt!G22:G31) | W29: =AVERAGE(MLX_per_prompt!H22:H31) | X29: =AVERAGE(MLX_per_prompt!I22:I31) | Y29: =AVERAGE(MLX_per_prompt!J22:J31) | Z29: =AVERAGE(MLX_per_prompt!K22:K31) | AA29: =AVERAGE(MLX_per_prompt!L22:L31)
A30: Large | B30: Qwen2-VL-7B-Instruct | C30: 8.29B | D30: NA | E30: NA | F30: NA | G30: NA | H30: NA | I30: NA | J30: NA | K30: NA | L30: NA | M30: NA | N30: NA | O30: Qwen2.5-VL-32B-Instruct | P30: 33.5B | Q30: =AVERAGE(MLX_per_prompt!M32:M41) | R30: =AVERAGE(MLX_per_prompt!N32:N41) | S30: NA | T30: NA | U30: =1/Q30 | V30: =AVERAGE(MLX_per_prompt!G32:G41) | W30: =AVERAGE(MLX_per_prompt!H32:H41) | X30: =AVERAGE(MLX_per_prompt!I32:I41) | Y30: =AVERAGE(MLX_per_prompt!J32:J41) | Z30: =AVERAGE(MLX_per_prompt!K32:K41) | AA30: =AVERAGE(MLX_per_prompt!L32:L41)
A32: MLX vs Hugging Face
A33: Size | B33: Inference rate: MLX ÷ HF (x faster) | C33: Inference time: HF ÷ MLX (x shorter) | D33: Models compared (HF vs MLX)
A34: Small | B34: =Q29/D29 | C34: =E29/R29 | D34: =B29&" vs "&O29
A35: Large | B35: NA | C35: NA | D35: =B30&" vs "&O30
A37: Comparison insights
A38: 1. Small: Qwen2.5-VL-3B on MLX generates 198.6 tokens/s vs 30.54 for Qwen2-VL-2B on Hugging Face (6.5x), and takes 2.22 s vs 2.93 s per video (1.3x shorter). These are different models, so this isn't like-for-like.
A39: 2. Large: Qwen2.5-VL-32B is by far the heaviest VTT model: 26.5 tokens/s, 25.73 s per video on MLX. The Hugging Face Large metrics weren't provided, so that comparison is NA.
A40: 3. The 32B model writes long, structured descriptions (526 output tokens on average vs 207 for 3B), which together with its lower speed explains its 12x longer time per video.
A41: 4. Qwen2.5-VL-3B got stuck repeating itself on prompt 02 (the 30-second street video) and hit the 1024-token limit; Qwen2.5-VL-32B finished every description.
A42: 5. MLX extra metrics: time to first token 1115 / 5788 ms, prompt processing rate 3231 / 524 tokens/s (3B / 32B), with 2,928 input tokens on average. These are NA for Hugging Face.
A43: 6. The Qwen2.5-VL Medium model (7B) also ran on MLX but isn't shown, because the VTT comparison has only Small and Large.
A49: VTT model metrics: comparison for SmolVLM2 family Hugging Face framework vs MLX framework
A51: Size | B51: Hugging Face framework | O51: MLX framework
B52: Model | C52: Parameters | D52: Avg Inference Rate (tokens/s) | E52: Avg Inference Time (s) | F52: Avg Video Processing Time (s) | G52: Avg Total Time (s) | H52: Avg Time per Output Token (s) | I52: Avg Frames Sampled | J52: Avg Input Tokens | K52: Avg Output Tokens | L52: Avg Output Words | M52: Avg Time to First Token (ms) | N52: Avg Prompt Processing Rate (tokens/s) | O52: Model | P52: Parameters | Q52: Avg Inference Rate (tokens/s) | R52: Avg Inference Time (s) | S52: Avg Video Processing Time (s) | T52: Avg Total Time (s) | U52: Avg Time per Output Token (s) | V52: Avg Frames Sampled | W52: Avg Input Tokens | X52: Avg Output Tokens | Y52: Avg Output Words | Z52: Avg Time to First Token (ms) | AA52: Avg Prompt Processing Rate (tokens/s)
A53: Small | B53: Qwen2-VL-2B-Instruct | C53: 2.21B | D53: 30.54 | E53: 2.93 | F53: 0.0311 | G53: 2.97 | H53: =1/D53 | I53: NA | J53: NA | K53: 88.17 | L53: NA | M53: NA | N53: NA | O53: SmolVLM2-256M-Video-Instruct | P53: 0.26B | Q53: =AVERAGE(MLX_per_prompt!M42:M51) | R53: =AVERAGE(MLX_per_prompt!N42:N51) | S53: NA | T53: NA | U53: =1/Q53 | V53: =AVERAGE(MLX_per_prompt!G42:G51) | W53: =AVERAGE(MLX_per_prompt!H42:H51) | X53: =AVERAGE(MLX_per_prompt!I42:I51) | Y53: =AVERAGE(MLX_per_prompt!J42:J51) | Z53: =AVERAGE(MLX_per_prompt!K42:K51) | AA53: =AVERAGE(MLX_per_prompt!L42:L51)
A54: Large | B54: Qwen2-VL-7B-Instruct | C54: 8.29B | D54: NA | E54: NA | F54: NA | G54: NA | H54: NA | I54: NA | J54: NA | K54: NA | L54: NA | M54: NA | N54: NA | O54: SmolVLM2-2.2B-Instruct | P54: 2.25B | Q54: =AVERAGE(MLX_per_prompt!M52:M61) | R54: =AVERAGE(MLX_per_prompt!N52:N61) | S54: NA | T54: NA | U54: =1/Q54 | V54: =AVERAGE(MLX_per_prompt!G52:G61) | W54: =AVERAGE(MLX_per_prompt!H52:H61) | X54: =AVERAGE(MLX_per_prompt!I52:I61) | Y54: =AVERAGE(MLX_per_prompt!J52:J61) | Z54: =AVERAGE(MLX_per_prompt!K52:K61) | AA54: =AVERAGE(MLX_per_prompt!L52:L61)
A56: MLX vs Hugging Face
A57: Size | B57: Inference rate: MLX ÷ HF (x faster) | C57: Inference time: HF ÷ MLX (x shorter) | D57: Models compared (HF vs MLX)
A58: Small | B58: =Q53/D53 | C58: =E53/R53 | D58: =B53&" vs "&O53
...

Sheet MLX_per_prompt
A1: family | B1: size | C1: parameters | D1: model | E1: prompt_id | F1: video_duration (s) | G1: frames_sampled | H1: input_tokens | I1: output_tokens | J1: output_words | K1: time_to_first_token (ms) | L1: prompt_processing_rate (tokens/s) | M1: inference_rate (tokens/s) | N1: inference_time (s)
A2: Qwen2-VL | B2: SMALL | C2: 2B | D2: Qwen2-VL-2B-Instruct | E2: 01 | F2: 10 | G2: 10 | H2: 2580 | I2: 163 | J2: 144 | K2: 973.7 | L2: 3070.1 | M2: 315.47 | N2: 1.493
A3: Qwen2-VL | B3: SMALL | C3: 2B | D3: Qwen2-VL-2B-Instruct | E3: 02 | F3: 30 | G3: 30 | H3: 7680 | I3: 93 | J3: 81 | K3: 3342.8 | L3: 2862.9 | M3: 269.03 | N3: 3.692
A4: Qwen2-VL | B4: SMALL | C4: 2B | D4: Qwen2-VL-2B-Instruct | E4: 03 | F4: 9.9 | G4: 8 | H4: 2070 | I4: 99 | J4: 85 | K4: 778.6 | L4: 3003.4 | M4: 313.63 | N4: 1.097
A5: Qwen2-VL | B5: SMALL | C5: 2B | D5: Qwen2-VL-2B-Instruct | E5: 04 | F5: 10 | G5: 10 | H5: 2580 | I5: 119 | J5: 100 | K5: 1002.4 | L5: 2954.2 | M5: 305.18 | N5: 1.395
A6: Qwen2-VL | B6: SMALL | C6: 2B | D6: Qwen2-VL-2B-Instruct | E6: 05 | F6: 10 | G6: 10 | H6: 2580 | I6: 92 | J6: 79 | K6: 1003.6 | L6: 2937.8 | M6: 305.32 | N6: 1.308
A7: Qwen2-VL | B7: SMALL | C7: 2B | D7: Qwen2-VL-2B-Instruct | E7: 06 | F7: 10 | G7: 10 | H7: 2580 | I7: 177 | J7: 156 | K7: 1016.6 | L7: 2998.1 | M7: 311.25 | N7: 1.588
A8: Qwen2-VL | B8: SMALL | C8: 2B | D8: Qwen2-VL-2B-Instruct | E8: 07 | F8: 10 | G8: 10 | H8: 2580 | I8: 183 | J8: 163 | K8: 1053.5 | L8: 3020 | M8: 312.77 | N8: 1.641
A9: Qwen2-VL | B9: SMALL | C9: 2B | D9: Qwen2-VL-2B-Instruct | E9: 08 | F9: 10 | G9: 10 | H9: 2580 | I9: 125 | J9: 110 | K9: 976.4 | L9: 2988.5 | M9: 307.77 | N9: 1.385
A10: Qwen2-VL | B10: SMALL | C10: 2B | D10: Qwen2-VL-2B-Instruct | E10: 09 | F10: 10 | G10: 10 | H10: 1475 | I10: 135 | J10: 116 | K10: 500.7 | L10: 3529.1 | M10: 321.11 | N10: 0.924
A11: Qwen2-VL | B11: SMALL | C11: 2B | D11: Qwen2-VL-2B-Instruct | E11: 10 | F11: 10 | G11: 10 | H11: 2580 | I11: 121 | J11: 104 | K11: 1068.8 | L11: 3023 | M11: 312 | N11: 1.459
A12: Qwen2-VL | B12: LARGE | C12: 7B | D12: Qwen2-VL-7B-Instruct | E12: 01 | F12: 10 | G12: 10 | H12: 2580 | I12: 122 | J12: 110 | K12: 1701.7 | L12: 1639 | M12: 111.02 | N12: 2.806
A13: Qwen2-VL | B13: LARGE | C13: 7B | D13: Qwen2-VL-7B-Instruct | E13: 02 | F13: 30 | G13: 30 | H13: 7680 | I13: 132 | J13: 115 | K13: 5441.8 | L13: 1609 | M13: 102.85 | N13: 6.73
... A61: SmolVLM2 | B61: LARGE | C61: 2.2B | D61: SmolVLM2-2.2B-Instruct | E61: 10 | F61: 10 | G61: 10 | H61: 857 | I61: 181 | J61: 153 | K61: 435.7 | L61: 3142.7 | M61: 135.49 | N61: 1.774
