Workbook

Sheet Comparison
A1: TTT model metrics: comparison for Falcon3 family Hugging Face framework vs MLX framework
A3: Size | B3: Hugging Face framework | L3: MLX framework
B4: Model | C4: Parameters | D4: Avg Inference Rate (tokens/s) | E4: Avg Inference Time (s) | F4: Avg Time per Output Token (s) | G4: Avg Input Tokens | H4: Avg Output Tokens | I4: Avg Output Words | J4: Avg Time to First Token (ms) | K4: Avg Prompt Processing Rate (tokens/s) | L4: Model | M4: Parameters | N4: Avg Inference Rate (tokens/s) | O4: Avg Inference Time (s) | P4: Avg Time per Output Token (s) | Q4: Avg Input Tokens | R4: Avg Output Tokens | S4: Avg Output Words | T4: Avg Time to First Token (ms) | U4: Avg Prompt Processing Rate (tokens/s)
A5: Small | B5: Phi-3-mini-128k-instruct | C5: 3.82B | D5: 37.23 | E5: 17.23 | F5: =1/D5 | G5: NA | H5: NA | I5: NA | J5: NA | K5: NA | L5: Falcon3-3B-Instruct | M5: 3.23B | N5: =AVERAGE(MLX_per_prompt!K2:K11) | O5: =AVERAGE(MLX_per_prompt!L2:L11) | P5: =1/N5 | Q5: =AVERAGE(MLX_per_prompt!F2:F11) | R5: =AVERAGE(MLX_per_prompt!G2:G11) | S5: =AVERAGE(MLX_per_prompt!H2:H11) | T5: =AVERAGE(MLX_per_prompt!I2:I11) | U5: =AVERAGE(MLX_per_prompt!J2:J11)
A6: Medium | B6: Llama-2-7b-hf | C6: 6.74B | D6: 17.15 | E6: 33.21 | F6: =1/D6 | G6: NA | H6: NA | I6: NA | J6: NA | K6: NA | L6: Falcon3-7B-Instruct | M6: 7.46B | N6: =AVERAGE(MLX_per_prompt!K12:K21) | O6: =AVERAGE(MLX_per_prompt!L12:L21) | P6: =1/N6 | Q6: =AVERAGE(MLX_per_prompt!F12:F21) | R6: =AVERAGE(MLX_per_prompt!G12:G21) | S6: =AVERAGE(MLX_per_prompt!H12:H21) | T6: =AVERAGE(MLX_per_prompt!I12:I21) | U6: =AVERAGE(MLX_per_prompt!J12:J21)
A7: Large | B7: falcon-11b | C7: 11.1B | D7: 10.52 | E7: 51.21 | F7: =1/D7 | G7: NA | H7: NA | I7: NA | J7: NA | K7: NA | L7: Falcon3-10B-Instruct | M7: 10.31B | N7: =AVERAGE(MLX_per_prompt!K22:K31) | O7: =AVERAGE(MLX_per_prompt!L22:L31) | P7: =1/N7 | Q7: =AVERAGE(MLX_per_prompt!F22:F31) | R7: =AVERAGE(MLX_per_prompt!G22:G31) | S7: =AVERAGE(MLX_per_prompt!H22:H31) | T7: =AVERAGE(MLX_per_prompt!I22:I31) | U7: =AVERAGE(MLX_per_prompt!J22:J31)
A9: MLX vs Hugging Face
A10: Size | B10: Inference rate: MLX ÷ HF (x faster) | C10: Inference time: HF ÷ MLX (x shorter) | D10: Models compared (HF vs MLX)
A11: Small | B11: =N5/D5 | C11: =E5/O5 | D11: =B5&" vs "&L5
A12: Medium | B12: =N6/D6 | C12: =E6/O6 | D12: =B6&" vs "&L6
A13: Large | B13: =N7/D7 | C13: =E7/O7 | D13: =B7&" vs "&L7
A15: Comparison insights
A16: 1. MLX generates text much faster at every size: 247.7 vs 37.23 tokens/s for Small (6.7x), 115.3 vs 17.15 for Medium (6.7x) and 81.9 vs 10.52 for Large (7.8x).
A17: 2. Average time per prompt is far lower on MLX: 2.88 s vs 17.23 s (Small), 6.05 s vs 33.21 s (Medium), 7.77 s vs 51.21 s (Large), i.e. 6.0x / 5.5x / 6.6x shorter.
A18: 3. Both frameworks slow down as models grow. From Small to Large, the inference rate drops 3.5x on Hugging Face and 3.0x on MLX, roughly in line with the growth in parameter count.
A19: 4. MLX reports more metrics: input and output tokens, output words, time to first token (75 / 105 / 134 ms) and prompt processing rate. These are NA for Hugging Face because they weren't provided.
A20: 5. MLX answers average 688 / 684 / 623 output tokens, so the MLX inference time includes ~500-word answers. Hugging Face output lengths aren't known, so its inference times can't be compared on equal output length; the inference rate (tokens/s) is the fairer comparison.
A21: 6. Caveat: the two frameworks ran different models. Hugging Face used Phi-3-mini-128k-instruct (3.82B), Llama-2-7b-hf (6.74B) and falcon-11b (11.1B); MLX used Falcon3-3B, 7B and 10B. The sizes are close but not identical, so part of the speed gap comes from the models themselves. A like-for-like test would run the same model on both frameworks.
A27: TTT model metrics: comparison for Llama-2 family Hugging Face framework vs MLX framework
A29: Size | B29: Hugging Face framework | L29: MLX framework
B30: Model | C30: Parameters | D30: Avg Inference Rate (tokens/s) | E30: Avg Inference Time (s) | F30: Avg Time per Output Token (s) | G30: Avg Input Tokens | H30: Avg Output Tokens | I30: Avg Output Words | J30: Avg Time to First Token (ms) | K30: Avg Prompt Processing Rate (tokens/s) | L30: Model | M30: Parameters | N30: Avg Inference Rate (tokens/s) | O30: Avg Inference Time (s) | P30: Avg Time per Output Token (s) | Q30: Avg Input Tokens | R30: Avg Output Tokens | S30: Avg Output Words | T30: Avg Time to First Token (ms) | U30: Avg Prompt Processing Rate (tokens/s)
A31: Small | B31: Phi-3-mini-128k-instruct | C31: 3.82B | D31: 37.23 | E31: 17.23 | F31: =1/D31 | G31: NA | H31: NA | I31: NA | J31: NA | K31: NA | L31: Llama-2-7b-hf | M31: 6.74B | N31: =AVERAGE(MLX_per_prompt!K32:K41) | O31: =AVERAGE(MLX_per_prompt!L32:L41) | P31: =1/N31 | Q31: =AVERAGE(MLX_per_prompt!F32:F41) | R31: =AVERAGE(MLX_per_prompt!G32:G41) | S31: =AVERAGE(MLX_per_prompt!H32:H41) | T31: =AVERAGE(MLX_per_prompt!I32:I41) | U31: =AVERAGE(MLX_per_prompt!J32:J41)
A32: Medium | B32: Llama-2-7b-hf | C32: 6.74B | D32: 17.15 | E32: 33.21 | F32: =1/D32 | G32: NA | H32: NA | I32: NA | J32: NA | K32: NA | L32: Llama-2-13b-hf | M32: 13.0B | N32: NA | O32: NA | P32: NA | Q32: NA | R32: NA | S32: NA | T32: NA | U32: NA
A33: Large | B33: falcon-11b | C33: 11.1B | D33: 10.52 | E33: 51.21 | F33: =1/D33 | G33: NA | H33: NA | I33: NA | J33: NA | K33: NA | L33: Llama-2-70b-hf | M33: 69.0B | N33: NA | O33: NA | P33: NA | Q33: NA | R33: NA | S33: NA | T33: NA | U33: NA
A35: MLX vs Hugging Face
A36: Size | B36: Inference rate: MLX ÷ HF (x faster) | C36: Inference time: HF ÷ MLX (x shorter) | D36: Models compared (HF vs MLX)
A37: Small | B37: =N31/D31 | C37: =E31/O31 | D37: =B31&" vs "&L31
A38: Medium | B38: NA | C38: NA | D38: =B32&" vs "&L32
A39: Large | B39: NA | C39: NA | D39: =B33&" vs "&L33
A40: Same model | B40: =N31/D32 | C40: =E32/O31 | D40: =B32&" vs "&L31
A42: Comparison insights
A43: 1. Same model, both frameworks: Llama-2-7b-hf runs at 121.0 tokens/s on MLX vs 17.15 tokens/s on Hugging Face, 7.1x faster. This is one of only two like-for-like comparisons in the file (the other is Phi-3-mini in the Phi-3 section); see the 'Same model' row in the table above.
A44: 2. Average time per prompt for that model is 4.07 s on MLX vs 33.21 s on Hugging Face (8.2x shorter).
A45: 3. Against the Hugging Face Small model (Phi-3-mini-128k-instruct, 3.82B), the larger Llama-2-7b-hf on MLX is still 3.3x faster (121.0 vs 37.23 tokens/s).
A46: 4. Llama-2-7b-hf is a base (not chat) model, so answer length varies widely: prompts 04, 06, 07 hit the 1024-token limit with repeated text, while prompts 10, 03, 05 stopped after only 76, 127, 138 tokens. The average time (4.07 s) depends heavily on these, so the inference rate (tokens/s) is the better measure.
A47: 5. MLX extra metrics for Llama-2-7b-hf: 62.5 input tokens on average (the base-model prompt wrapper adds tokens), 84 ms time to first token and 875 tokens/s prompt processing rate. These are NA for Hugging Face.
A48: 6. Medium and Large are NA on MLX: Llama-2-13b-hf hasn't been run yet, and Llama-2-70b-hf (~39 GB) doesn't fit in this Mac's 40.2 GB GPU memory budget. Note also that the Hugging Face results label Llama-2-7b-hf as Medium, while in the Llama-2 family it is the Small model (7B / 13B / 70B).
A54: TTT model metrics: comparison for Llama-3 family Hugging Face framework vs MLX framework
A56: Size | B56: Hugging Face framework | L56: MLX framework
B57: Model | C57: Parameters | D57: Avg Inference Rate (tokens/s) | E57: Avg Inference Time (s) | F57: Avg Time per Output Token (s) | G57: Avg Input Tokens | H57: Avg Output Tokens | I57: Avg Output Words | J57: Avg Time to First Token (ms) | K57: Avg Prompt Processing Rate (tokens/s) | L57: Model | M57: Parameters | N57: Avg Inference Rate (tokens/s) | O57: Avg Inference Time (s) | P57: Avg Time per Output Token (s) | Q57: Avg Input Tokens | R57: Avg Output Tokens | S57: Avg Output Words | T57: Avg Time to First Token (ms) | U57: Avg Prompt Processing Rate (tokens/s)
...

Sheet MLX_per_prompt
A1: family | B1: size | C1: parameters | D1: model | E1: prompt_id | F1: input_tokens | G1: output_tokens | H1: output_words | I1: time_to_first_token (ms) | J1: prompt_processing_rate (tokens/s) | K1: inference_rate (tokens/s) | L1: inference_time (s)
A2: Falcon3 | B2: SMALL | C2: 3B | D2: Falcon3-3B-Instruct | E2: 01 | F2: 36 | G2: 333 | H2: 254 | I2: 80.6 | J2: 813.7 | K2: 262.93 | L2: 1.353
A3: Falcon3 | B3: SMALL | C3: 3B | D3: Falcon3-3B-Instruct | E3: 02 | F3: 43 | G3: 751 | H3: 528 | I3: 75.8 | J3: 1206.5 | K3: 254.18 | L3: 3.037
A4: Falcon3 | B4: SMALL | C4: 3B | D4: Falcon3-3B-Instruct | E4: 03 | F4: 38 | G4: 606 | H4: 470 | I4: 78.2 | J4: 1043.7 | K4: 258.57 | L4: 2.428
A5: Falcon3 | B5: SMALL | C5: 3B | D5: Falcon3-3B-Instruct | E5: 04 | F5: 39 | G5: 722 | H5: 525 | I5: 72.7 | J5: 1094.1 | K5: 244.83 | L5: 3.029
A6: Falcon3 | B6: SMALL | C6: 3B | D6: Falcon3-3B-Instruct | E6: 05 | F6: 70 | G6: 607 | H6: 468 | I6: 74 | J6: 1860.1 | K6: 243.35 | L6: 2.575
A7: Falcon3 | B7: SMALL | C7: 3B | D7: Falcon3-3B-Instruct | E7: 06 | F7: 24 | G7: 705 | H7: 525 | I7: 71.4 | J7: 823.4 | K7: 244.53 | L7: 2.962
A8: Falcon3 | B8: SMALL | C8: 3B | D8: Falcon3-3B-Instruct | E8: 07 | F8: 24 | G8: 1024 | H8: 668 | I8: 80.3 | J8: 641.9 | K8: 238.18 | L8: 4.387
A9: Falcon3 | B9: SMALL | C9: 3B | D9: Falcon3-3B-Instruct | E9: 08 | F9: 48 | G9: 607 | H9: 435 | I9: 74.7 | J9: 1290.8 | K9: 245.7 | L9: 2.552
A10: Falcon3 | B10: SMALL | C10: 3B | D10: Falcon3-3B-Instruct | E10: 09 | F10: 33 | G10: 887 | H10: 606 | I10: 65.1 | J10: 1151.4 | K10: 238.9 | L10: 3.785
A11: Falcon3 | B11: SMALL | C11: 3B | D11: Falcon3-3B-Instruct | E11: 10 | F11: 36 | G11: 635 | H11: 483 | I11: 78.1 | J11: 994.9 | K11: 246.28 | L11: 2.664
A12: Falcon3 | B12: MEDIUM | C12: 7B | D12: Falcon3-7B-Instruct | E12: 01 | F12: 36 | G12: 500 | H12: 424 | I12: 109.6 | J12: 504.6 | K12: 117.14 | L12: 4.386
A13: Falcon3 | B13: MEDIUM | C13: 7B | D13: Falcon3-7B-Instruct | E13: 02 | F13: 43 | G13: 577 | H13: 436 | I13: 120.3 | J13: 536.7 | K13: 114.89 | L13: 5.15
... A131: Qwen2.5 | B131: MEDIUM | C131: 14B | D131: Qwen2.5-14B-Instruct | E131: 10 | F131: 55 | G131: 914 | H131: 684 | I131: 156.6 | J131: 506.9 | K131: 60.54 | L131: 15.262
