Workbook

Sheet Comparison
A1: ITT model metrics: comparison for Qwen2-VL family Hugging Face framework vs MLX framework
A3: Size | B3: Hugging Face framework | N3: MLX framework
B4: Model | C4: Parameters | D4: Avg Inference Rate (tokens/s) | E4: Avg Inference Time (s) | F4: Avg Image Processing Time (s) | G4: Avg Total Time (s) | H4: Avg Time per Output Token (s) | I4: Avg Input Tokens | J4: Avg Output Tokens | K4: Avg Output Words | L4: Avg Time to First Token (ms) | M4: Avg Prompt Processing Rate (tokens/s) | N4: Model | O4: Parameters | P4: Avg Inference Rate (tokens/s) | Q4: Avg Inference Time (s) | R4: Avg Image Processing Time (s) | S4: Avg Total Time (s) | T4: Avg Time per Output Token (s) | U4: Avg Input Tokens | V4: Avg Output Tokens | W4: Avg Output Words | X4: Avg Time to First Token (ms) | Y4: Avg Prompt Processing Rate (tokens/s)
A5: Small | B5: Qwen2-VL-2B-Instruct | C5: 2.21B | D5: 21.12 | E5: 5.3245 | F5: 0.0597 | G5: 5.3842 | H5: 0.05067 | I5: NA | J5: 113.6 | K5: NA | L5: NA | M5: NA | N5: Qwen2-VL-2B-Instruct | O5: 2.21B | P5: =AVERAGE(MLX_per_prompt!L2:L11) | Q5: =AVERAGE(MLX_per_prompt!M2:M11) | R5: NA | S5: NA | T5: =1/P5 | U5: =AVERAGE(MLX_per_prompt!G2:G11) | V5: =AVERAGE(MLX_per_prompt!H2:H11) | W5: =AVERAGE(MLX_per_prompt!I2:I11) | X5: =AVERAGE(MLX_per_prompt!J2:J11) | Y5: =AVERAGE(MLX_per_prompt!K2:K11)
A6: Large | B6: Qwen2-VL-7B-Instruct | C6: 8.29B | D6: 13.55 | E6: 10.9016 | F6: 0.0627 | G6: 10.9643 | H6: 0.08325 | I6: NA | J6: 161.5 | K6: NA | L6: NA | M6: NA | N6: Qwen2-VL-7B-Instruct | O6: 8.29B | P6: =AVERAGE(MLX_per_prompt!L12:L21) | Q6: =AVERAGE(MLX_per_prompt!M12:M21) | R6: NA | S6: NA | T6: =1/P6 | U6: =AVERAGE(MLX_per_prompt!G12:G21) | V6: =AVERAGE(MLX_per_prompt!H12:H21) | W6: =AVERAGE(MLX_per_prompt!I12:I21) | X6: =AVERAGE(MLX_per_prompt!J12:J21) | Y6: =AVERAGE(MLX_per_prompt!K12:K21)
A8: MLX vs Hugging Face
A9: Size | B9: Inference rate: MLX ÷ HF (x faster) | C9: Inference time: HF ÷ MLX (x shorter) | D9: Models compared (HF vs MLX)
A10: Small | B10: =P5/D5 | C10: =E5/Q5 | D10: =B5&" vs "&N5
A11: Large | B11: =P6/D6 | C11: =E6/Q6 | D11: =B6&" vs "&N6
A13: Comparison insights
A14: 1. Same models, both frameworks: both rows compare Qwen2-VL with itself, so this is the fairest ITT comparison. Qwen2-VL-2B generates 316.0 tokens/s on MLX vs 21.12 on Hugging Face (15.0x faster), and Qwen2-VL-7B 113.7 vs 13.55 (8.4x faster).
A15: 2. Time per image is 4.01 s vs 5.3245 s for 2B (1.3x shorter) and 5.63 s vs 10.9016 s for 7B (1.9x shorter). The time gap is smaller than the speed gap because MLX wrote longer descriptions and spends time reading the image first (see insights 3 and 4).
A16: 3. MLX wrote longer descriptions than Hugging Face: 198 vs 113.6 output tokens (2B) and 239 vs 161.5 (7B).
A17: 4. Qwen2-VL keeps images at close to their native resolution, so each image becomes ~2,460 input tokens on average; reading them takes 3388 ms (2B) and 3521 ms (7B) before the first word appears on MLX.
A18: 5. Moving from 2B to 7B costs 1.6x in speed on Hugging Face and 2.8x on MLX, so MLX's advantage is largest on the small model.
A19: 6. Hugging Face also reports image processing time (0.0597 / 0.0627 s) and total time (5.3842 / 10.9643 s); MLX doesn't time image loading separately, so those are NA on MLX. Neither MLX model hit the 1024-token limit.
A25: ITT model metrics: comparison for Qwen2.5-VL family Hugging Face framework vs MLX framework
A27: Size | B27: Hugging Face framework | N27: MLX framework
B28: Model | C28: Parameters | D28: Avg Inference Rate (tokens/s) | E28: Avg Inference Time (s) | F28: Avg Image Processing Time (s) | G28: Avg Total Time (s) | H28: Avg Time per Output Token (s) | I28: Avg Input Tokens | J28: Avg Output Tokens | K28: Avg Output Words | L28: Avg Time to First Token (ms) | M28: Avg Prompt Processing Rate (tokens/s) | N28: Model | O28: Parameters | P28: Avg Inference Rate (tokens/s) | Q28: Avg Inference Time (s) | R28: Avg Image Processing Time (s) | S28: Avg Total Time (s) | T28: Avg Time per Output Token (s) | U28: Avg Input Tokens | V28: Avg Output Tokens | W28: Avg Output Words | X28: Avg Time to First Token (ms) | Y28: Avg Prompt Processing Rate (tokens/s)
A29: Small | B29: Qwen2-VL-2B-Instruct | C29: 2.21B | D29: 21.12 | E29: 5.3245 | F29: 0.0597 | G29: 5.3842 | H29: 0.05067 | I29: NA | J29: 113.6 | K29: NA | L29: NA | M29: NA | N29: Qwen2.5-VL-3B-Instruct | O29: 3.75B | P29: =AVERAGE(MLX_per_prompt!L22:L31) | Q29: =AVERAGE(MLX_per_prompt!M22:M31) | R29: NA | S29: NA | T29: =1/P29 | U29: =AVERAGE(MLX_per_prompt!G22:G31) | V29: =AVERAGE(MLX_per_prompt!H22:H31) | W29: =AVERAGE(MLX_per_prompt!I22:I31) | X29: =AVERAGE(MLX_per_prompt!J22:J31) | Y29: =AVERAGE(MLX_per_prompt!K22:K31)
A30: Large | B30: Qwen2-VL-7B-Instruct | C30: 8.29B | D30: 13.55 | E30: 10.9016 | F30: 0.0627 | G30: 10.9643 | H30: 0.08325 | I30: NA | J30: 161.5 | K30: NA | L30: NA | M30: NA | N30: Qwen2.5-VL-32B-Instruct | O30: 33.5B | P30: =AVERAGE(MLX_per_prompt!L32:L41) | Q30: =AVERAGE(MLX_per_prompt!M32:M41) | R30: NA | S30: NA | T30: =1/P30 | U30: =AVERAGE(MLX_per_prompt!G32:G41) | V30: =AVERAGE(MLX_per_prompt!H32:H41) | W30: =AVERAGE(MLX_per_prompt!I32:I41) | X30: =AVERAGE(MLX_per_prompt!J32:J41) | Y30: =AVERAGE(MLX_per_prompt!K32:K41)
A32: MLX vs Hugging Face
A33: Size | B33: Inference rate: MLX ÷ HF (x faster) | C33: Inference time: HF ÷ MLX (x shorter) | D33: Models compared (HF vs MLX)
A34: Small | B34: =P29/D29 | C34: =E29/Q29 | D34: =B29&" vs "&N29
A35: Large | B35: =P30/D30 | C35: =E30/Q30 | D35: =B30&" vs "&N30
A37: Comparison insights
A38: 1. Small: Qwen2.5-VL-3B on MLX shows 200.9 tokens/s vs 21.12 for Qwen2-VL-2B on Hugging Face (9.5x), but this figure is unreliable (see insight 2). These are different models, so this isn't like-for-like.
A39: 2. Qwen2.5-VL-3B produced only '!!!!…' on 3 of 10 images (prompts 04, 05, 09), running to the 1024-token limit. That's why it averages 471 output tokens but only 115 words; its speed and time numbers should be treated with caution.
A40: 3. Large: Qwen2.5-VL-32B on MLX generates 26.2 tokens/s vs 13.55 for Qwen2-VL-7B on Hugging Face (1.9x), even though it is about four times larger. Time per image is 29.20 s vs 10.9016 s.
A41: 4. Qwen2.5-VL-32B writes the longest, most detailed descriptions (629 output tokens, 461 words on average), which is why its time per image is 2.7x the Hugging Face Qwen2-VL-7B time despite the faster token rate.
A42: 5. MLX extra metrics: time to first token 1022 / 5087 ms and prompt processing rate 2217 / 412 tokens/s (3B / 32B), with ~2,460 input tokens per image. These are NA for Hugging Face.
A43: 6. The Qwen2.5-VL Medium model (7B) also ran on MLX but isn't shown, because the ITT comparison has only Small and Large.
A49: ITT model metrics: comparison for Gemma-3 family Hugging Face framework vs MLX framework
A51: Size | B51: Hugging Face framework | N51: MLX framework
B52: Model | C52: Parameters | D52: Avg Inference Rate (tokens/s) | E52: Avg Inference Time (s) | F52: Avg Image Processing Time (s) | G52: Avg Total Time (s) | H52: Avg Time per Output Token (s) | I52: Avg Input Tokens | J52: Avg Output Tokens | K52: Avg Output Words | L52: Avg Time to First Token (ms) | M52: Avg Prompt Processing Rate (tokens/s) | N52: Model | O52: Parameters | P52: Avg Inference Rate (tokens/s) | Q52: Avg Inference Time (s) | R52: Avg Image Processing Time (s) | S52: Avg Total Time (s) | T52: Avg Time per Output Token (s) | U52: Avg Input Tokens | V52: Avg Output Tokens | W52: Avg Output Words | X52: Avg Time to First Token (ms) | Y52: Avg Prompt Processing Rate (tokens/s)
A53: Small | B53: Qwen2-VL-2B-Instruct | C53: 2.21B | D53: 21.12 | E53: 5.3245 | F53: 0.0597 | G53: 5.3842 | H53: 0.05067 | I53: NA | J53: 113.6 | K53: NA | L53: NA | M53: NA | N53: gemma-3-4b-it | O53: 4.3B | P53: =AVERAGE(MLX_per_prompt!L42:L51) | Q53: =AVERAGE(MLX_per_prompt!M42:M51) | R53: NA | S53: NA | T53: =1/P53 | U53: =AVERAGE(MLX_per_prompt!G42:G51) | V53: =AVERAGE(MLX_per_prompt!H42:H51) | W53: =AVERAGE(MLX_per_prompt!I42:I51) | X53: =AVERAGE(MLX_per_prompt!J42:J51) | Y53: =AVERAGE(MLX_per_prompt!K42:K51)
A54: Large | B54: Qwen2-VL-7B-Instruct | C54: 8.29B | D54: 13.55 | E54: 10.9016 | F54: 0.0627 | G54: 10.9643 | H54: 0.08325 | I54: NA | J54: 161.5 | K54: NA | L54: NA | M54: NA | N54: gemma-3-27b-it | O54: 27.4B | P54: =AVERAGE(MLX_per_prompt!L52:L61) | Q54: =AVERAGE(MLX_per_prompt!M52:M61) | R54: NA | S54: NA | T54: =1/P54 | U54: =AVERAGE(MLX_per_prompt!G52:G61) | V54: =AVERAGE(MLX_per_prompt!H52:H61) | W54: =AVERAGE(MLX_per_prompt!I52:I61) | X54: =AVERAGE(MLX_per_prompt!J52:J61) | Y54: =AVERAGE(MLX_per_prompt!K52:K61)
A56: MLX vs Hugging Face
A57: Size | B57: Inference rate: MLX ÷ HF (x faster) | C57: Inference time: HF ÷ MLX (x shorter) | D57: Models compared (HF vs MLX)
A58: Small | B58: =P53/D53 | C58: =E53/Q53 | D58: =B53&" vs "&N53
...

Sheet MLX_per_prompt
A1: family | B1: size | C1: parameters | D1: model | E1: prompt_id | F1: image_size (px) | G1: input_tokens | H1: output_tokens | I1: output_words | J1: time_to_first_token (ms) | K1: prompt_processing_rate (tokens/s) | L1: inference_rate (tokens/s) | M1: inference_time (s)
A2: Qwen2-VL | B2: SMALL | C2: 2B | D2: Qwen2-VL-2B-Instruct | E2: 01 | F2: 1024x1024 | G2: 1396 | H2: 148 | I2: 125 | J2: 763.2 | K2: 1925.2 | L2: 311.99 | M2: 1.241
A3: Qwen2-VL | B3: SMALL | C3: 2B | D3: Qwen2-VL-2B-Instruct | E3: 02 | F3: 270x187 | G3: 97 | H3: 644 | I3: 422 | J3: 63.2 | K3: 1636.7 | L3: 345.34 | M3: 1.931
A4: Qwen2-VL | B4: SMALL | C4: 2B | D4: Qwen2-VL-2B-Instruct | E4: 03 | F4: 352x339 | G4: 183 | H4: 120 | I4: 91 | J4: 80.9 | K4: 2398.1 | L4: 355.43 | M4: 0.421
A5: Qwen2-VL | B5: SMALL | C5: 2B | D5: Qwen2-VL-2B-Instruct | E5: 04 | F5: 2048x2048 | G5: 5356 | H5: 98 | I5: 85 | J5: 8329.6 | K5: 649.6 | L5: 275.81 | M5: 8.688
A6: Qwen2-VL | B6: SMALL | C6: 2B | D6: Qwen2-VL-2B-Instruct | E6: 05 | F6: 2048x1365 | G6: 3604 | H6: 130 | I6: 112 | J6: 3933.8 | K6: 931.2 | L6: 290.63 | M6: 4.384
A7: Qwen2-VL | B7: SMALL | C7: 2B | D7: Qwen2-VL-2B-Instruct | E7: 06 | F7: 1920x1080 | G7: 2718 | H7: 208 | I7: 126 | J7: 2425.1 | K7: 1141.5 | L7: 301.49 | M7: 3.118
A8: Qwen2-VL | B8: SMALL | C8: 2B | D8: Qwen2-VL-2B-Instruct | E8: 07 | F8: 2240x1400 | G8: 4027 | H8: 291 | I8: 200 | J8: 4687.4 | K8: 871.1 | L8: 297.31 | M8: 5.669
A9: Qwen2-VL | B9: SMALL | C9: 2B | D9: Qwen2-VL-2B-Instruct | E9: 08 | F9: 299x168 | G9: 93 | H9: 71 | I9: 53 | J9: 61.3 | K9: 1588.8 | L9: 362.15 | M9: 0.26
A10: Qwen2-VL | B10: SMALL | C10: 2B | D10: Qwen2-VL-2B-Instruct | E10: 09 | F10: 2048x2688 | G10: 7035 | H10: 108 | I10: 91 | J10: 13471.1 | K10: 526 | L10: 264.91 | M10: 13.882
A11: Qwen2-VL | B11: SMALL | C11: 2B | D11: Qwen2-VL-2B-Instruct | E11: 10 | F11: 251x200 | G11: 90 | H11: 166 | I11: 138 | J11: 62.4 | K11: 1508.9 | L11: 355.34 | M11: 0.532
A12: Qwen2-VL | B12: LARGE | C12: 7B | D12: Qwen2-VL-7B-Instruct | E12: 01 | F12: 1024x1024 | G12: 1396 | H12: 110 | I12: 91 | J12: 983.8 | K12: 1472.8 | L12: 114.85 | M12: 1.946
A13: Qwen2-VL | B13: LARGE | C13: 7B | D13: Qwen2-VL-7B-Instruct | E13: 02 | F13: 270x187 | G13: 97 | H13: 489 | I13: 307 | J13: 88.1 | K13: 1139.3 | L13: 117.78 | M13: 4.245
... A81: SmolVLM | B81: LARGE | C81: 2.2B | D81: SmolVLM-Instruct | E81: 10 | F81: 251x200 | G81: 1562 | H81: 104 | I81: 89 | J81: 519.4 | K81: 3392.8 | L81: 246.55 | M81: 0.946
