Workbook

Sheet Comparison
A1: STT model metrics: comparison for Whisper family Hugging Face framework vs MLX framework
A3: Size | B3: Hugging Face framework | L3: MLX framework
B4: Model | C4: Parameters | D4: Avg Inference Rate (tokens/s) | E4: Avg Inference Time (s) | F4: Avg Time per Output Token (s) | G4: Avg Time to First Token (ms) | H4: Avg Input Audio (s) | I4: Avg Input Tokens | J4: Avg Output Tokens | K4: Avg Output Words | L4: Model | M4: Parameters | N4: Avg Inference Rate (tokens/s) | O4: Avg Inference Time (s) | P4: Avg Time per Output Token (s) | Q4: Avg Time to First Token (ms) | R4: Avg Input Audio (s) | S4: Avg Input Tokens | T4: Avg Output Tokens | U4: Avg Output Words
A5: Small | B5: Whisper medium | C5: 0.76B | D5: 21.43 | E5: 26.72 | F5: 0.05264 | G5: 1430 | H5: NA | I5: NA | J5: 505.4 | K5: NA | L5: whisper-small | M5: 0.24B | N5: =AVERAGE(MLX_per_clip!L2:L11) | O5: =AVERAGE(MLX_per_clip!M2:M11) | P5: =1/N5 | Q5: =AVERAGE(MLX_per_clip!K2:K11) | R5: =AVERAGE(MLX_per_clip!G2:G11) | S5: =AVERAGE(MLX_per_clip!H2:H11) | T5: =AVERAGE(MLX_per_clip!I2:I11) | U5: =AVERAGE(MLX_per_clip!J2:J11)
A6: Medium | B6: Whisper large | C6: 1.55B | D6: NA | E6: NA | F6: NA | G6: NA | H6: NA | I6: NA | J6: NA | K6: NA | L6: whisper-medium | M6: 0.76B | N6: =AVERAGE(MLX_per_clip!L12:L21) | O6: =AVERAGE(MLX_per_clip!M12:M21) | P6: =1/N6 | Q6: =AVERAGE(MLX_per_clip!K12:K21) | R6: =AVERAGE(MLX_per_clip!G12:G21) | S6: =AVERAGE(MLX_per_clip!H12:H21) | T6: =AVERAGE(MLX_per_clip!I12:I21) | U6: =AVERAGE(MLX_per_clip!J12:J21)
A8: MLX vs Hugging Face
A9: Size | B9: Inference rate: MLX ÷ HF (x faster) | C9: Inference time: HF ÷ MLX (x shorter) | D9: Models compared (HF vs MLX)
A10: Small | B10: =N5/D5 | C10: =E5/O5 | D10: =B5&" vs "&L5
A11: Medium | B11: NA | C11: NA | D11: =B6&" vs "&L6
A12: Same model | B12: =N6/D5 | C12: =E5/O6 | D12: =B5&" vs "&L6
A14: Comparison insights
A15: 1. Same model, both frameworks: Whisper medium runs at 116.7 tokens/s on MLX vs 21.43 on Hugging Face, 5.4x faster (see the 'Same model' row; Hugging Face lists it as Small, while in the MLX Whisper family it is the Medium model).
A16: 2. Time per clip is 0.195 s on MLX vs 26.72 s on Hugging Face, but this isn't a fair comparison: the Hugging Face run produced 505.4 output tokens per clip on average, while the MLX clips (~8.3 s of speech each) produced only 24. The Hugging Face run likely used much longer audio, so the inference rate is the fairer measure.
A17: 3. Time to first token is 195 ms on MLX vs 1430 ms on Hugging Face for Whisper medium (7.3x quicker on MLX).
A18: 4. Small: whisper-small on MLX runs at 219.9 tokens/s vs 21.43 for Whisper medium on Hugging Face (10.3x). Medium: the Hugging Face Whisper large metrics weren't provided, so that row is NA; whisper-medium on MLX runs at 116.7 tokens/s.
A19: 5. On MLX, whisper-small is 1.9x faster than whisper-medium and both produce transcripts of the same length (19.3 / 19.3 words), but whisper-small misheard 'Prime Minister' as 'crime minister' and 'Cessna' as 'ASESNA'; whisper-medium got both right. (Every Whisper model heard 'Mia's' as 'Maya's' on clip 05.)
A20: 6. Whisper always encodes a 30-second audio window, so every clip uses 1500 input tokens regardless of its length. whisper-large-v3 also ran on MLX but isn't shown, because the STT comparison has only Small and Medium.
A26: STT model metrics: comparison for Whisper.en family Hugging Face framework vs MLX framework
A28: Size | B28: Hugging Face framework | L28: MLX framework
B29: Model | C29: Parameters | D29: Avg Inference Rate (tokens/s) | E29: Avg Inference Time (s) | F29: Avg Time per Output Token (s) | G29: Avg Time to First Token (ms) | H29: Avg Input Audio (s) | I29: Avg Input Tokens | J29: Avg Output Tokens | K29: Avg Output Words | L29: Model | M29: Parameters | N29: Avg Inference Rate (tokens/s) | O29: Avg Inference Time (s) | P29: Avg Time per Output Token (s) | Q29: Avg Time to First Token (ms) | R29: Avg Input Audio (s) | S29: Avg Input Tokens | T29: Avg Output Tokens | U29: Avg Output Words
A30: Small | B30: Whisper medium | C30: 0.76B | D30: 21.43 | E30: 26.72 | F30: 0.05264 | G30: 1430 | H30: NA | I30: NA | J30: 505.4 | K30: NA | L30: whisper-base.en | M30: 0.07B | N30: =AVERAGE(MLX_per_clip!L22:L31) | O30: =AVERAGE(MLX_per_clip!M22:M31) | P30: =1/N30 | Q30: =AVERAGE(MLX_per_clip!K22:K31) | R30: =AVERAGE(MLX_per_clip!G22:G31) | S30: =AVERAGE(MLX_per_clip!H22:H31) | T30: =AVERAGE(MLX_per_clip!I22:I31) | U30: =AVERAGE(MLX_per_clip!J22:J31)
A31: Medium | B31: Whisper large | C31: 1.55B | D31: NA | E31: NA | F31: NA | G31: NA | H31: NA | I31: NA | J31: NA | K31: NA | L31: whisper-small.en | M31: 0.24B | N31: =AVERAGE(MLX_per_clip!L32:L41) | O31: =AVERAGE(MLX_per_clip!M32:M41) | P31: =1/N31 | Q31: =AVERAGE(MLX_per_clip!K32:K41) | R31: =AVERAGE(MLX_per_clip!G32:G41) | S31: =AVERAGE(MLX_per_clip!H32:H41) | T31: =AVERAGE(MLX_per_clip!I32:I41) | U31: =AVERAGE(MLX_per_clip!J32:J41)
A33: MLX vs Hugging Face
A34: Size | B34: Inference rate: MLX ÷ HF (x faster) | C34: Inference time: HF ÷ MLX (x shorter) | D34: Models compared (HF vs MLX)
A35: Small | B35: =N30/D30 | C35: =E30/O30 | D35: =B30&" vs "&L30
A36: Medium | B36: NA | C36: NA | D36: =B31&" vs "&L31
A38: Comparison insights
A39: 1. Small: whisper-base.en on MLX runs at 323.6 tokens/s vs 21.43 for Whisper medium on Hugging Face (15.1x faster). These are different models, so this isn't like-for-like.
A40: 2. Medium: whisper-small.en on MLX runs at 210.9 tokens/s and 0.107 s per clip. The Hugging Face Medium (Whisper large) metrics weren't provided, so that row is NA.
A41: 3. whisper-base.en is the fastest Whisper model on MLX: it transcribes a clip in 0.069 s with a 69 ms time to first token, 1.5x faster than whisper-small.en.
A42: 4. Both models produce the same transcript length (19.3 / 19.3 words) and both got 'Prime Minister' and 'Cessna 172N' right; whisper-base.en sometimes starts sentences in lower case, and both heard 'Mia's' as 'Maya's' on clip 05.
A43: 5. Time per clip is 0.069 s (base.en) and 0.107 s (small.en) on MLX vs 26.72 s on Hugging Face, but the Hugging Face run averaged 505.4 output tokens per clip against ~24 here, so the times aren't directly comparable.
A44: 6. whisper-medium.en also ran on MLX but isn't shown, because the STT comparison has only Small and Medium.
A50: STT model metrics: comparison for Parakeet family Hugging Face framework vs MLX framework
A52: Size | B52: Hugging Face framework | L52: MLX framework
B53: Model | C53: Parameters | D53: Avg Inference Rate (tokens/s) | E53: Avg Inference Time (s) | F53: Avg Time per Output Token (s) | G53: Avg Time to First Token (ms) | H53: Avg Input Audio (s) | I53: Avg Input Tokens | J53: Avg Output Tokens | K53: Avg Output Words | L53: Model | M53: Parameters | N53: Avg Inference Rate (tokens/s) | O53: Avg Inference Time (s) | P53: Avg Time per Output Token (s) | Q53: Avg Time to First Token (ms) | R53: Avg Input Audio (s) | S53: Avg Input Tokens | T53: Avg Output Tokens | U53: Avg Output Words
A54: Small | B54: Whisper medium | C54: 0.76B | D54: 21.43 | E54: 26.72 | F54: 0.05264 | G54: 1430 | H54: NA | I54: NA | J54: 505.4 | K54: NA | L54: parakeet-tdt_ctc-110m | M54: 0.12B | N54: =AVERAGE(MLX_per_clip!L42:L51) | O54: =AVERAGE(MLX_per_clip!M42:M51) | P54: =1/N54 | Q54: =AVERAGE(MLX_per_clip!K42:K51) | R54: =AVERAGE(MLX_per_clip!G42:G51) | S54: =AVERAGE(MLX_per_clip!H42:H51) | T54: =AVERAGE(MLX_per_clip!I42:I51) | U54: =AVERAGE(MLX_per_clip!J42:J51)
A55: Medium | B55: Whisper large | C55: 1.55B | D55: NA | E55: NA | F55: NA | G55: NA | H55: NA | I55: NA | J55: NA | K55: NA | L55: parakeet-tdt-0.6b-v2 | M55: 0.62B | N55: =AVERAGE(MLX_per_clip!L52:L61) | O55: =AVERAGE(MLX_per_clip!M52:M61) | P55: =1/N55 | Q55: =AVERAGE(MLX_per_clip!K52:K61) | R55: =AVERAGE(MLX_per_clip!G52:G61) | S55: =AVERAGE(MLX_per_clip!H52:H61) | T55: =AVERAGE(MLX_per_clip!I52:I61) | U55: =AVERAGE(MLX_per_clip!J52:J61)
A57: MLX vs Hugging Face
A58: Size | B58: Inference rate: MLX ÷ HF (x faster) | C58: Inference time: HF ÷ MLX (x shorter) | D58: Models compared (HF vs MLX)
...

Sheet MLX_per_clip
A1: family | B1: size | C1: parameters | D1: model | E1: clip_id | F1: voice | G1: input_audio (s) | H1: input_tokens | I1: output_tokens | J1: output_words | K1: time_to_first_token (ms) | L1: inference_rate (tokens/s) | M1: inference_time (s)
A2: Whisper | B2: SMALL | C2: 241M | D2: whisper-small | E2: 01 | F2: Samantha | G2: 6.87 | H2: 1500 | I2: 21 | J2: 18 | K2: 100.7 | L2: 208.6 | M2: 0.101
A3: Whisper | B3: SMALL | C3: 241M | D3: whisper-small | E3: 02 | F3: Daniel | G3: 9.76 | H3: 1500 | I3: 26 | J3: 22 | K3: 110.2 | L3: 235.8 | M3: 0.11
A4: Whisper | B4: SMALL | C4: 241M | D4: whisper-small | E4: 03 | F4: Karen | G4: 6.92 | H4: 1500 | I4: 24 | J4: 20 | K4: 102.2 | L4: 234.8 | M4: 0.102
A5: Whisper | B5: SMALL | C5: 241M | D5: whisper-small | E5: 04 | F5: Moira | G5: 8.86 | H5: 1500 | I5: 24 | J5: 20 | K5: 101.8 | L5: 235.7 | M5: 0.102
A6: Whisper | B6: SMALL | C6: 241M | D6: whisper-small | E6: 05 | F6: Rishi | G6: 19.13 | H6: 1500 | I6: 59 | J6: 42 | K6: 183.4 | L6: 321.8 | M6: 0.183
A7: Whisper | B7: SMALL | C7: 241M | D7: whisper-small | E7: 06 | F7: Samantha | G7: 3.08 | H7: 1500 | I7: 10 | J7: 8 | K7: 65.6 | L7: 152.4 | M7: 0.066
A8: Whisper | B8: SMALL | C8: 241M | D8: whisper-small | E8: 07 | F8: Daniel | G8: 3.32 | H8: 1500 | I8: 9 | J8: 8 | K8: 70.7 | L8: 127.3 | M8: 0.071
A9: Whisper | B9: SMALL | C9: 241M | D9: whisper-small | E9: 08 | F9: Karen | G9: 10.98 | H9: 1500 | I9: 34 | J9: 27 | K9: 124.8 | L9: 272.5 | M9: 0.125
A10: Whisper | B10: SMALL | C10: 241M | D10: whisper-small | E10: 09 | F10: Moira | G10: 7.27 | H10: 1500 | I10: 21 | J10: 15 | K10: 99.3 | L10: 211.5 | M10: 0.099
A11: Whisper | B11: SMALL | C11: 241M | D11: whisper-small | E11: 10 | F11: Rishi | G11: 6.63 | H11: 1500 | I11: 18 | J11: 13 | K11: 90.6 | L11: 198.6 | M11: 0.091
A12: Whisper | B12: MEDIUM | C12: 762M | D12: whisper-medium | E12: 01 | F12: Samantha | G12: 6.87 | H12: 1500 | I12: 21 | J12: 18 | K12: 182.1 | L12: 115.3 | M12: 0.182
A13: Whisper | B13: MEDIUM | C13: 762M | D13: whisper-medium | E13: 02 | F13: Daniel | G13: 9.76 | H13: 1500 | I13: 26 | J13: 22 | K13: 194.7 | L13: 133.6 | M13: 0.195
... A61: Parakeet | B61: MEDIUM | C61: 618M | D61: parakeet-tdt-0.6b-v2 | E61: 10 | F61: Rishi | G61: 6.63 | H61: 83 | I61: 35 | J61: 13 | K61: 81.7 | L61: 428.6 | M61: 0.082
