Workbook

Sheet Comparison
A1: TTS model metrics: comparison for Bark family Hugging Face framework vs MLX framework
A3: Size | B3: Hugging Face framework | O3: MLX framework
B4: Model | C4: Parameters | D4: Model Size (GB) | E4: Avg Synthesis Time (s) | F4: Avg Audio Duration (s) | G4: Avg Real-Time Factor (RTF) | H4: Avg Inference Rate (audio s/s) | I4: Avg Time to First Audio (ms) | J4: Avg Word Error Rate (%) | K4: Peak Memory (GB) | L4: Avg Input Words | M4: Avg Input Characters | N4: Sample Rate (Hz) | O4: Model | P4: Parameters | Q4: Model Size (GB) | R4: Avg Synthesis Time (s) | S4: Avg Audio Duration (s) | T4: Avg Real-Time Factor (RTF) | U4: Avg Inference Rate (audio s/s) | V4: Avg Time to First Audio (ms) | W4: Avg Word Error Rate (%) | X4: Peak Memory (GB) | Y4: Avg Input Words | Z4: Avg Input Characters | AA4: Sample Rate (Hz)
A5: Small | B5: Bark | C5: 1.1B | D5: 4.48 | E5: 67.65 | F5: 12.12 | G5: 5.56 | H5: =1/G5 | I5: NA | J5: NA | K5: NA | L5: NA | M5: NA | N5: NA | O5: bark-small | P5: 0.42B | Q5: 1.61 | R5: =AVERAGE(MLX_per_prompt!L2:L11) | S5: =AVERAGE(MLX_per_prompt!H2:H11) | T5: =R5/S5 | U5: =AVERAGE(MLX_per_prompt!K2:K11) | V5: =AVERAGE(MLX_per_prompt!J2:J11) | W5: =AVERAGE(MLX_per_prompt!M2:M11) | X5: 4.21 | Y5: =AVERAGE(MLX_per_prompt!F2:F11) | Z5: =AVERAGE(MLX_per_prompt!G2:G11) | AA5: 24000
A6: Medium | B6: seamless-m4t-v2-large | C6: 2.3B | D6: 8.61 | E6: 2.68 | F6: =E6/G6 | G6: 0.29 | H6: =1/G6 | I6: NA | J6: NA | K6: NA | L6: NA | M6: NA | N6: NA | O6: No Medium Bark model on MLX | P6: NA | Q6: NA | R6: NA | S6: NA | T6: NA | U6: NA | V6: NA | W6: NA | X6: NA | Y6: NA | Z6: NA | AA6: NA
A7: Large | B7: No Large model in the HF registry | C7: NA | D7: NA | E7: NA | F7: NA | G7: NA | H7: NA | I7: NA | J7: NA | K7: NA | L7: NA | M7: NA | N7: NA | O7: bark | P7: 1.1B | Q7: 4.42 | R7: =AVERAGE(MLX_per_prompt!L12:L21) | S7: =AVERAGE(MLX_per_prompt!H12:H21) | T7: =R7/S7 | U7: =AVERAGE(MLX_per_prompt!K12:K21) | V7: =AVERAGE(MLX_per_prompt!J12:J21) | W7: =AVERAGE(MLX_per_prompt!M12:M21) | X7: 7.25 | Y7: =AVERAGE(MLX_per_prompt!F12:F21) | Z7: =AVERAGE(MLX_per_prompt!G12:G21) | AA7: 24000
A9: MLX vs Hugging Face
A10: Size | B10: Real-time factor: HF ÷ MLX (x faster) | C10: Synthesis time: HF ÷ MLX (x shorter) | D10: Models compared (HF vs MLX)
A11: Small | B11: =G5/T5 | C11: =E5/R5 | D11: =B5&" vs "&O5
A12: Medium | B12: NA | C12: NA | D12: =B6&" vs "&O6
A13: Large | B13: NA | C13: NA | D13: =B7&" vs "&O7
A14: Same model | B14: =G5/T7 | C14: =E5/R7 | D14: =B5&" vs "&O7
A16: Comparison insights
A17: 1. Same model, both frameworks: the Hugging Face 'Bark' (4.48 GB) is the full Bark model, which is the Large size in the MLX Bark family (4.42 GB); see the 'Same model' row. Its real-time factor is 2.85 on MLX vs 5.56 on Hugging Face, 2.0x faster.
A18: 2. Bark is slower than real time on both frameworks: on MLX it takes 43.9 s to make 15.4 s of audio, against 67.65 s for 12.12 s on Hugging Face.
A19: 3. Small: bark-small on MLX runs close to real time (RTF 0.90, 15.2 s for 16.8 s of audio), 3.2x faster than full Bark on MLX.
A20: 4. Accuracy (word error rate of a Whisper transcript of the audio): full Bark 6.0% vs bark-small 19.0%. bark-small rambled on prompt 03 (118% WER); both models sometimes add filler words such as 'And' or 'Yeah'. Hugging Face WER wasn't provided.
A21: 5. Medium: the Hugging Face seamless-m4t-v2-large (RTF 0.29) has no MLX equivalent in the Bark family, so that row is NA on MLX.
A22: 6. Bark can't take a free-text voice description; the MLX runs picked a male or female preset voice from it. Time to first audio is 1499 / 3756 ms (small / full), since Bark produces each sentence in one go.
A28: TTS model metrics: comparison for Kitten-TTS family Hugging Face framework vs MLX framework
A30: Size | B30: Hugging Face framework | O30: MLX framework
B31: Model | C31: Parameters | D31: Model Size (GB) | E31: Avg Synthesis Time (s) | F31: Avg Audio Duration (s) | G31: Avg Real-Time Factor (RTF) | H31: Avg Inference Rate (audio s/s) | I31: Avg Time to First Audio (ms) | J31: Avg Word Error Rate (%) | K31: Peak Memory (GB) | L31: Avg Input Words | M31: Avg Input Characters | N31: Sample Rate (Hz) | O31: Model | P31: Parameters | Q31: Model Size (GB) | R31: Avg Synthesis Time (s) | S31: Avg Audio Duration (s) | T31: Avg Real-Time Factor (RTF) | U31: Avg Inference Rate (audio s/s) | V31: Avg Time to First Audio (ms) | W31: Avg Word Error Rate (%) | X31: Peak Memory (GB) | Y31: Avg Input Words | Z31: Avg Input Characters | AA31: Sample Rate (Hz)
A32: Small | B32: Bark | C32: 1.1B | D32: 4.48 | E32: 67.65 | F32: 12.12 | G32: 5.56 | H32: =1/G32 | I32: NA | J32: NA | K32: NA | L32: NA | M32: NA | N32: NA | O32: kitten-tts-nano | P32: 15M | Q32: 0.06 | R32: =AVERAGE(MLX_per_prompt!L22:L31) | S32: =AVERAGE(MLX_per_prompt!H22:H31) | T32: =R32/S32 | U32: =AVERAGE(MLX_per_prompt!K22:K31) | V32: =AVERAGE(MLX_per_prompt!J22:J31) | W32: =AVERAGE(MLX_per_prompt!M22:M31) | X32: 2.4 | Y32: =AVERAGE(MLX_per_prompt!F22:F31) | Z32: =AVERAGE(MLX_per_prompt!G22:G31) | AA32: 24000
A33: Medium | B33: seamless-m4t-v2-large | C33: 2.3B | D33: 8.61 | E33: 2.68 | F33: =E33/G33 | G33: 0.29 | H33: =1/G33 | I33: NA | J33: NA | K33: NA | L33: NA | M33: NA | N33: NA | O33: kitten-tts-micro | P33: 36M | Q33: 0.13 | R33: =AVERAGE(MLX_per_prompt!L32:L41) | S33: =AVERAGE(MLX_per_prompt!H32:H41) | T33: =R33/S33 | U33: =AVERAGE(MLX_per_prompt!K32:K41) | V33: =AVERAGE(MLX_per_prompt!J32:J41) | W33: =AVERAGE(MLX_per_prompt!M32:M41) | X33: 1.88 | Y33: =AVERAGE(MLX_per_prompt!F32:F41) | Z33: =AVERAGE(MLX_per_prompt!G32:G41) | AA33: 24000
A34: Large | B34: No Large model in the HF registry | C34: NA | D34: NA | E34: NA | F34: NA | G34: NA | H34: NA | I34: NA | J34: NA | K34: NA | L34: NA | M34: NA | N34: NA | O34: kitten-tts-mini | P34: 74M | Q34: 0.29 | R34: =AVERAGE(MLX_per_prompt!L42:L51) | S34: =AVERAGE(MLX_per_prompt!H42:H51) | T34: =R34/S34 | U34: =AVERAGE(MLX_per_prompt!K42:K51) | V34: =AVERAGE(MLX_per_prompt!J42:J51) | W34: =AVERAGE(MLX_per_prompt!M42:M51) | X34: 2.78 | Y34: =AVERAGE(MLX_per_prompt!F42:F51) | Z34: =AVERAGE(MLX_per_prompt!G42:G51) | AA34: 24000
A36: MLX vs Hugging Face
A37: Size | B37: Real-time factor: HF ÷ MLX (x faster) | C37: Synthesis time: HF ÷ MLX (x shorter) | D37: Models compared (HF vs MLX)
A38: Small | B38: =G32/T32 | C38: =E32/R32 | D38: =B32&" vs "&O32
A39: Medium | B39: =G33/T33 | C39: =E33/R33 | D39: =B33&" vs "&O33
A40: Large | B40: NA | C40: NA | D40: =B34&" vs "&O34
A42: Comparison insights
A43: 1. Kitten-TTS is tiny (15M to 74M parameters) and by far the fastest: kitten-tts-nano makes audio 92x faster than real time (RTF 0.011), 0.14 s per sentence.
A44: 2. Small: kitten-tts-nano's RTF is 521x lower than Bark's on Hugging Face (5.56). These are different models, so this isn't like-for-like.
A45: 3. Medium: kitten-tts-micro (RTF 0.032) is 9x faster than seamless-m4t-v2-large on Hugging Face (RTF 0.29), in 0.44 s vs 2.68 s per sentence.
A46: 4. Bigger isn't faster here: nano → micro → mini run at 92 / 31 / 26 audio seconds per second.
A47: 5. Accuracy is good for the size: 3.2% / 6.2% / 3.6% word error rate (nano / micro / mini), mostly from reading apostrophes as separate letters ('it s', 'Don T').
A48: 6. Large: kitten-tts-mini has no Hugging Face counterpart in the registry, so that row is NA on the Hugging Face side. Kitten-TTS uses preset voices, not free-text descriptions.
A54: TTS model metrics: comparison for Qwen3-TTS family Hugging Face framework vs MLX framework
A56: Size | B56: Hugging Face framework | O56: MLX framework
B57: Model | C57: Parameters | D57: Model Size (GB) | E57: Avg Synthesis Time (s) | F57: Avg Audio Duration (s) | G57: Avg Real-Time Factor (RTF) | H57: Avg Inference Rate (audio s/s) | I57: Avg Time to First Audio (ms) | J57: Avg Word Error Rate (%) | K57: Peak Memory (GB) | L57: Avg Input Words | M57: Avg Input Characters | N57: Sample Rate (Hz) | O57: Model | P57: Parameters | Q57: Model Size (GB) | R57: Avg Synthesis Time (s) | S57: Avg Audio Duration (s) | T57: Avg Real-Time Factor (RTF) | U57: Avg Inference Rate (audio s/s) | V57: Avg Time to First Audio (ms) | W57: Avg Word Error Rate (%) | X57: Peak Memory (GB) | Y57: Avg Input Words | Z57: Avg Input Characters | AA57: Sample Rate (Hz)
...

Sheet MLX_per_prompt
A1: family | B1: size | C1: model | D1: prompt_id | E1: voice | F1: input_words | G1: input_characters | H1: output_audio (s) | I1: sample_rate (Hz) | J1: time_to_first_audio (ms) | K1: inference_rate (audio s/s) | L1: inference_time (s) | M1: word_error_rate (%)
A2: Bark | B2: SMALL | C2: bark-small | D2: 01 | E2: en_speaker_6 | F2: 34 | G2: 227 | H2: 28.63 | I2: 24000 | J2: 943.1 | K2: 1.16 | L2: 24.672 | M2: 2.94
A3: Bark | B3: SMALL | C3: bark-small | D3: 02 | E3: en_speaker_9 | F3: 22 | G3: 149 | H3: 18.15 | I3: 24000 | J3: 882.8 | K3: 1.12 | L3: 16.145 | M3: 4.35
A4: Bark | B4: SMALL | C4: bark-small | D4: 03 | E4: en_speaker_6 | F4: 28 | G4: 157 | H4: 20.27 | I4: 24000 | J4: 2787.6 | K4: 1.13 | L4: 17.923 | M4: 117.86
A5: Bark | B5: SMALL | C5: bark-small | D5: 04 | E5: en_speaker_9 | F5: 29 | G5: 155 | H5: 13.05 | I5: 24000 | J5: 1767.3 | K5: 1.11 | L5: 11.714 | M5: 13.79
A6: Bark | B6: SMALL | C6: bark-small | D6: 05 | E6: en_speaker_6 | F6: 25 | G6: 150 | H6: 11.59 | I6: 24000 | J6: 1512.2 | K6: 1.1 | L6: 10.562 | M6: 15.38
A7: Bark | B7: SMALL | C7: bark-small | D7: 06 | E7: en_speaker_9 | F7: 26 | G7: 155 | H7: 19.77 | I7: 24000 | J7: 892.9 | K7: 1.08 | L7: 18.328 | M7: 7.69
A8: Bark | B8: SMALL | C8: bark-small | D8: 07 | E8: en_speaker_6 | F8: 31 | G8: 189 | H8: 16.8 | I8: 24000 | J8: 3117.6 | K8: 1.09 | L8: 15.343 | M8: 0
A9: Bark | B9: SMALL | C9: bark-small | D9: 08 | E9: en_speaker_9 | F9: 28 | G9: 155 | H9: 18.4 | I9: 24000 | J9: 1283.9 | K9: 1.07 | L9: 17.121 | M9: 7.14
A10: Bark | B10: SMALL | C10: bark-small | D10: 09 | E10: en_speaker_6 | F10: 23 | G10: 143 | H10: 8.96 | I10: 24000 | J10: 954.4 | K10: 1.04 | L10: 8.636 | M10: 8.7
A11: Bark | B11: SMALL | C11: bark-small | D11: 10 | E11: en_speaker_6 | F11: 25 | G11: 155 | H11: 12.8 | I11: 24000 | J11: 852.6 | K11: 1.08 | L11: 11.808 | M11: 12
A12: Bark | B12: LARGE | C12: bark | D12: 01 | E12: en_speaker_6 | F12: 34 | G12: 227 | H12: 24.4 | I12: 24000 | J12: 1718.9 | K12: 0.33 | L12: 73.56 | M12: 11.76
A13: Bark | B13: LARGE | C13: bark | D13: 02 | E13: en_speaker_9 | F13: 22 | G13: 149 | H13: 18.64 | I13: 24000 | J13: 1138.2 | K13: 0.34 | L13: 54.31 | M13: 21.74
... A81: OuteTTS | B81: MEDIUM | C81: OuteTTS-1.0-1B | D81: 10 | E81: default | F81: 25 | G81: 155 | H81: 10.72 | I81: 24000 | J81: 11663.6 | K81: 0.92 | L81: 11.673 | M81: 0
